Workbook

Sheet قائمة الموارد المالية
G1: المملكة المغربية
G2: وزارة الداخلية
G3: جهة درعة تافيلالت
G4: إقـليــم تــنــغيــر
I5: جماعة سوق الخميس دادس
B6: قائمة الموارد المالية
A7: برسم سنة 2024 | F7: الجزء الاول : المداخيل
A9: نسبة التحصيل | B9: الموارد المالية التي لم يتم تحصيلها | C9: الموارد المالية التي تم تحصيلها | D9: الصافي من المداخيل المقررة | E9: المسجل بالميزانية | F9: نوع المدخول المالي
A10: 0 | B10: 0 | C10: 51500 | D10: 51500 | E10: 65000 | F10: رسم تصديق الإمضاء والإشهاد بالتطابق | G10: 10 | H10: 00-10 | I10: 10-11
A11: 1 | B11: 0 | C11: 48542 | D11: 48542 | E11: 62000 | F11: رسوم الحالة المدنية | G11: 10 | H11: 00-10 | I11: 30-31
A12: 0 | B12: 0 | C12: 0 | D12: 0 | E12: 0 | F12: ترقيم العقارات | G12: 10 | H12: 00-20 | I12: 30.31
A13: 0 | B13: 0 | C13: 0 | D13: 0 | E13: 0 | F13: تسجيل بيع البهائم | G13: 10 | H13: 00-20 | I13: 30.32
A14: 0 | B14: 0 | C14: 0 | D14: 0 | E14: 10 | F14: صوائر أبحاث المنافع والمضار | G14: 10 | H14: 00-20 | I14: 30.33
A15: 0 | B15: 0 | C15: 0 | D15: 0 | E15: 10 | F15: منتوج بيع أثاث وأدوات ومواد استغني عنها | G15: 10 | H15: 00-30 | I15: 20.21
A16: 0 | B16: 0 | C16: 0 | D16: 0 | E16: 10 | F16: منتوج بيع التصاميم والمطبوعات وملفات المزايدة | G16: 10 | H16: 00-30 | I16: 20.23
A17: 0 | B17: 0 | C17: 0 | D17: 0 | E17: 10 | F17: منتوج بيع الحيوانات والأشياء المحجوزة والتي لم تسحب داخل الآجال المحددة | G17: 10 | H17: 00-30 | I17: 20.24
A18: 0 | B18: 0 | C18: 0 | D18: 0 | E18: 10 | F18: المتحصل من الدعائر الجبائية و التراضي فيما يتعلق بالضرائب | G18: 10 | H18: 00-40 | I18: 10.11
A19: 0 | B19: 0 | C19: 0 | D19: 0 | E19: 10 | F19: النسبة المئوية المقبوضة في البيوعات العمومية | G19: 10 | H19: 00-40 | I19: 10.12
A20: 1 | B20: 0 | C20: 217.86 | D20: 217.86 | E20: 385.12 | F20: اقتطاع من المداخيل المحققة لفائدة الغير | G20: 10 | H20: 00-40 | I20: 30.31
A21: 0 | B21: 0 | C21: 0 | D21: 0 | E21: 0 | F21: رسم المحجز | G21: 10 | H21: 00-40 | I21: 30-32
A22: 1 | B22: 0 | C22: 7564000 | D22: 7564000 | E22: 7564000 | F22: حصة من منتوج الضريبة على القيمة المضافة | G22: 10 | H22: 00-50 | I22: 10
A23: 0 | B23: 0 | C23: 0 | D23: 0 | E23: 10 | F23: حق الإمتياز في مصلحة سيارة الإسعاف الجماعية | G23: 20 | H23: 00-10 | I23: 30
A24: 1 | B24: 0 | C24: 1200 | D24: 1200 | E24: 5000 | F24: استرجاع صوائر النقل بواسطة سيارة الإسعاف | G24: 20 | H24: 00-10 | I24: 30.31
A25: 0 | B25: 0 | C25: 0 | D25: 0 | E25: 0 | F25: مدخول مصلحة إفراغ حفرات المراحيض وتنظيف القنوات | G25: 20 | H25: 00-10 | I25: 30.32
A26: 1 | B26: 0 | C26: 47250 | D26: 47250 | E26: 60000 | F26: الإتصال بشبكة الماء الحار | G26: 20 | H26: 00-10 | I26: 30.34
A27: 0 | B27: 0 | C27: 0 | D27: 0 | E27: 0 | F27: استرجاع صوائر التنظيف | G27: 20 | H27: 00-10 | I27: 30.35
A28: 0 | B28: 0 | C28: 0 | D28: 0 | E28: 0 | F28: ما يؤدى للجماعة لأجل أشغال متعلقة بالصحة العمومية أو الأمن العام أجرتها على نفقة ملاكين قاصرين | G28: 20 | H28: 00-10 | I28: 30.36
A29: 0 | B29: 0 | C29: 0 | D29: 0 | E29: 0 | F29: مدخول الخزانة الجماعية | G29: 20 | H29: 00-20 | I29: 30.32
A30: 0 | B30: 0 | C30: 2764 | D30: 2764 | E30: 1500 | F30: الرسم المفروض على الإقامة في المؤسسات السياحية | G30: 20 | H30: 00-30 | I30: 10-11
A31: 0 | B31: 0 | C31: 0 | D31: 0 | E31: 10 | F31: الضريبة المفروضة على الملاهي | G31: 20 | H31: 00-30 | I31: 12
A32: 0 | B32: 0 | C32: 0 | D32: 0 | F32: ضريبة المباني | G32: 30 | H32: 00-10 | I32: 10-11
A33: 0 | B33: 0 | C33: 0 | D33: 0 | E33: 0 | F33: ضريبة الصيانة المفروضة على الأملاك الخاضعة لضريبة المباني | G33: 30 | H33: 00-10 | I33: 10-12
A34: 0 | B34: 0 | C34: 0 | D34: 0 | E34: 0 | F34: الضريبة على الأراضي الحضرية غير المبنية | G34: 30 | H34: 00-10 | I34: 10-14
A35: 1 | B35: 0 | C35: 41540 | D35: 41540 | E35: 120000 | F35: الضريبة على عمليات البناء | G35: 30 | H35: 00-10 | I35: 10-15
A36: 0 | B36: 0 | C36: 0 | D36: 0 | E36: 0 | F36: الضريبة على عمليات تجزئة الأراضي | G36: 30 | H36: 00-10 | I36: 10-16
A37: 0 | B37: 0 | C37: 0 | D37: 0 | E37: 0 | F37: رسم السكن | G37: 30 | H37: 00-10 | I37: 10-18
A38: 0 | B38: 0 | C38: 0 | D38: 0 | E38: 10 | F38: رسم الخدمات الجماعية | G38: 30 | H38: 00-10 | I38: 10-19
A39: 0 | B39: 0 | C39: 0 | D39: 0 | E39: 0 | F39: حصة من منتوج الرسم على الخدمات الجماعية | G39: 30 | H39: 00-10 | I39: 10-20
A40: 0 | B40: 0 | C40: 35100 | D40: 35100 | E40: 100000 | F40: الرسم المفروض على شغل الأملاك الجماعية العامة مؤقتا لأغراض ترتبط بالبناء | G40: 30 | H40: 00-10 | I40: 20.22
A41: 1 | B41: 0 | C41: 18249 | D41: 18249 | E41: 31000 | F41: منتوج كراء بنايات للسكنى | G41: 30 | H41: 00-10 | I41: 20.23
...

Sheet قائمة مصاريف التسيير
G1: =+'قائمة الموارد المالية'!G1:J1 -> المملكة المغربية
G2: =+'قائمة الموارد المالية'!G2:J2 -> وزارة الداخلية
G3: =+'قائمة الموارد المالية'!G3:J3 -> جهة درعة تافيلالت
G4: =+'قائمة الموارد المالية'!G4:J4 -> إقـليــم تــنــغيــر
G5: ='قائمة الموارد المالية'!I5 -> جماعة سوق الخميس دادس
B6: قائمة مصاريف التسيير
A7: برسم سنة 2024
A9: الإعتمادات المنقولة | B9: الإعتمادات الملغاة | C9: الحوالات الصادرة و المؤشر عليها | D9: المصاريف الملتزم بها | E9: مجموع الإعتمادات المفتوحة | F9: نوع المصاريف
A12: 0 | B12: 1750 | C12: 300650 | D12: 302400 | E12: 302400 | F12: تعويضات للرئيس، ولذوي الحق من المستشارين | G12: 10.11 | H12: 10 | I12: 10
A13: 0 | B13: 0 | C13: 0 | D13: 0 | E13: 0 | F13: مصاريف نقل الرئيس والمستشارين داخل المملكة | G13: 10.12 | H13: 10 | I13: 10
A14: 0 | B14: 13280 | C14: 21720 | D14: 21720 | E14: 35000 | F14: مصاريف تنقل الرئيس والمستشارين داخل المملكة | G14: 10.14 | H14: 10 | I14: 10
A15: 0 | B15: 0 | C15: 10000 | D15: 10000 | E15: 10000 | F15: مصاريف تأمين الأعضاء | G15: 10.16 | H15: 10 | I15: 10
A16: 12120 | B16: 17880 | C16: 0 | D16: 12120 | E16: 30000 | F16: شراء عتاد صغير للتزيين | G16: 20.21 | H16: 10 | I16: 10
A17: 0 | B17: 39440 | C17: 10560 | D17: 10560 | E17: 50000 | F17: مصاريف الإقامة والإطعام والإستقبال | G17: 20.24 | H17: 10 | I17: 10
A18: 0 | B18: 0 | C18: 0 | D18: 0 | E18: 0 | F18: اشتراك في الجرائد الرسمية والجرائد والمجلات | G18: 50.51 | H18: 10 | I18: 10
A19: 0 | B19: 785604.45 | C19: 2056395.6 | D19: 2056395.6 | E19: 2842000 | F19: الرواتب والتعويضات القارة للموظفين الرسميين ومتلائمهم | G19: 10.11 | H19: 20 | I19: 10
A20: 0 | B20: 478.54 | C20: 359521.46 | D20: 359521.46 | E20: 360000 | F20: أجور الأعوان العرضيين | G20: 10.14 | H20: 20 | I20: 10
A21: 0 | B21: 0 | C21: 22000 | D21: 22000 | E21: 22000 | F21: تعويضات عن الأشغال الإضافية | G21: 20.21 | H21: 20 | I21: 10
A22: 0 | B22: 0 | C22: 600 | D22: 600 | E22: 600 | F22: تعويضات عن الصندوق | G22: 20.22 | H22: 20 | I22: 10
A23: 0 | B23: 10901.13 | C23: 79098.87 | D23: 79098.87 | E23: 90000 | F23: التعويضات عن الأشغال الشاقة والموسخة | G23: 20.24 | H23: 20 | I23: 10
... A50: 0 | B50: 120 | C50: 12000 | D50: 12000 | E50: 12120 | F50: مصاريف تهيئ لوائح اجور الموظفين من طرف مؤسسات اخرى | G50: 80.83 | H50: 30 | I50: 10
B51: 10000 | C51: 0 | D51: 0 | E51: 10000 | F51: مصاريف مختلفة للخدمات الرقمية | G51: 90.9 | H51: 30 | I51: 10
A52: 0 | B52: 0 | C52: 300000 | D52: 300000 | E52: 300000 | F52: مستحقات استهلاك الكهرباء | G52: 90.91 | H52: 30 | I52: 10
A53: 0 | B53: 0 | C53: 60000 | D53: 60000 | E53: 60000 | F53: مستحقات استهلاك الهاتف | G53: 90.94 | H53: 30 | I53: 10
A54: 0 | B54: 8000 | C54: 0 | D54: 0 | E54: 8000 | F54: رسوم بريدية ومصاريف المراسلات | G54: 90.95 | H54: 30 | I54: 10
A55: 0 | B55: 5.19 | C55: 6994.81 | D55: 6994.81 | E55: 7000 | F55: التأمين عن الحريق وعن المسؤولية المدنية | G55: 90.96 | H55: 30 | I55: 10
A56: 30288 | B56: 39712 | C56: 0 | D56: 30288 | E56: 70000 | F56: إعلانات قانونية ، إدراجات و مصاريف النشر | G56: 90.97 | H56: 30 | I56: 10
A57: 0 | B57: 0 | C57: 354401.79 | D57: 354401.79 | E57: 354401.79 | F57: فوائد القرض رقم الممنوح من طرف ص. ت .ج | G57: 10.11 | H57: 40 | I57: 10
A58: 0 | B58: 934.35 | C58: 5969.47 | D58: 5969.47 | E58: 6903.82 | F58: فوائد التاخير | G58: 20.21 | H58: 40 | I58: 10
A59: 0 | B59: 500 | C59: 49500 | D59: 49500 | E59: 50000 | F59: إعانات مقدمة لجمعيات الأعمال الإجتماعية للموظفين | G59: 10.11 | H59: 10 | I59: 20
A60: 0 | B60: 2000 | C60: 368000 | D60: 368000 | E60: 370000 | F60: إعانات مقدمة للأعمال الإنسانية | G60: 10.13 | H60: 10 | I60: 20
A61: 0 | B61: 0 | C61: 100000 | D61: 100000 | E61: 100000 | F61: إعانات لمؤسسات أخرى اجتماعية | G61: 10.14 | H61: 10 | I61: 20
B62: 3000 | C62: 0 | D62: 0 | E62: 3000 | F62: المساهمة في موسسة الاعمال الاجتماعية لموظفي الجماعات الترابية | G62: 10.15 | H62: 10 | I62: 20
A63: 0 | B63: 2192.56 | C63: 157807.44 | D63: 157807.44 | E63: 160000 | F63: شراء مواد غدائية | G63: 20.25 | H63: 10 | I63: 20
A64: 0 | B64: 10000 | C64: 0 | D64: 0 | E64: 10000 | F64: إعانات للجمعيات الرياضية | G64: 10.11 | H64: 20 | I64: 20
A65: 0 | B65: 12000 | C65: 0 | D65: 0 | E65: 12000 | F65: شراء المواد الصحية للمكاتب البلدية الصحية والمراكز الإستشفائية | G65: 10.11 | H65: 30 | I65: 20
A66: 0 | B66: 0 | C66: 0 | D66: 0 | E66: 0 | F66: شراء كتب لمنح الجوائز | G66: 10.13 | H66: 60 | I66: 20
A67: 0 | B67: 10000 | C67: 0 | D67: 0 | E67: 10000 | F67: مصاريف التكوين المستمر للمنتخبين | G67: 10.13 | H67: 70 | I67: 20
A68: 0 | B68: 0 | C68: 0 | D68: 0 | E68: 0 | F68: مصاريف التكوين المستمر لموظفي الجماعة | G68: 10.14 | H68: 70 | I68: 20
A69: 0 | B69: 0 | C69: 0 | D69: 0 | E69: 0 | F69: تسفير الكتب والسجلات المختلفة | G69: 10.14 | H69: 80 | I69: 20
...

Sheet قائمة مصاريف التجهيز
G1: =+'قائمة مصاريف التسيير'!G1:J1 -> المملكة المغربية
G2: =+'قائمة مصاريف التسيير'!G2:J2 -> وزارة الداخلية
G3: =+'قائمة مصاريف التسيير'!G3:J3 -> جهة درعة تافيلالت
C4: قائمة مصاريف التجهيز | G4: =+'قائمة مصاريف التسيير'!G4:J4 -> إقـليــم تــنــغيــر
B5: برسم سنة 2024 | G5: =+'قائمة مصاريف التسيير'!G5:J5 -> جماعة سوق الخميس دادس
A7: الإعتمادات الملغاة | B7: الإعتمادات المنقولة | C7: الحوالات الصادرة و المؤشر عليها | D7: المصاريف الملتزم بها | E7: الإعتمادات النهائية | F7: نوع المصاريف
A9: 0 | B9: 92639 | C9: 0 | D9: 0 | E9: 92639 | F9: الأراضي (الإقتناءات) | G9: 1110 | H9: 1010 | I9: 10 | J9: 4 | K9: 2
A10: 0 | B10: 94841 | C10: 0 | D10: 0 | E10: 94841 | F10: الدراسات و المساعدة التقنية | G10: 2110 | H10: 1010 | I10: 10 | J10: 4 | K10: 2
A11: 0 | B11: 0 | C11: 0 | D11: 0 | E11: 0 | F11: البنايات | G11: 3310 | H11: 1010 | I11: 10 | J11: 4 | K11: 2
A12: 0 | B12: 300598 | C12: 0 | D12: 0 | E12: 300598 | F12: السيارات الدراجات و الدراجات النارية | G12: 1120 | H12: 1010 | I12: 10 | J12: 4 | K12: 2
A13: 0 | B13: 0 | C13: 0 | D13: 0 | E13: 0 | F13: العتاد التقني | G13: 1320 | H13: 1010 | I13: 10 | J13: 4 | K13: 2
A14: 0 | B14: 0 | C14: 0 | D14: 0 | E14: 0 | F14: العتاد المعلوماتي | G14: 1420 | H14: 1010 | I14: 10 | J14: 4 | K14: 2
A15: 0 | B15: 0 | C15: 0 | D15: 0 | E15: 0 | F15: العتاد الكهربائي و الالكتروني | G15: 1520 | H15: 1010 | I15: 10 | J15: 4 | K15: 2
A16: 0 | B16: 0 | C16: 0 | D16: 0 | E16: 0 | F16: عتاد التزيين و الحفلات | G16: 1620 | H16: 1010 | I16: 10 | J16: 4 | K16: 2
A17: 0 | B17: 400000 | C17: 0 | D17: 0 | E17: 400000 | F17: السيارات الدراجات و الدراجات النارية و الاليات | G17: 2120 | H17: 1010 | I17: 10 | J17: 4 | K17: 2
A18: 0 | B18: 63000 | C18: 0 | D18: 61702.92 | E18: 63000 | F18: العتاد التقني | G18: 2220 | H18: 1010 | I18: 10 | J18: 4 | K18: 2
A19: 0 | B19: 5656 | C19: 31344 | D19: 31344 | E19: 37000 | F19: العتاد المعلوماتي و البرمجيات | G19: 2320 | H19: 1010 | I19: 10 | J19: 4 | K19: 2
A20: 0 | B20: 13969.47 | C20: 504626.64 | D20: 504626.64 | E20: 518596.11 | F20: سداد اصل القرض رقم ACR005569MAD | G20: 1310 | H20: 4040 | I20: 10 | J20: 4 | K20: 2
A21: 0 | B21: 400000 | C21: 0 | D21: 0 | E21: 400000 | F21: الاراضي | G21: 1210 | H21: 1010 | I21: 20 | J21: 4 | K21: 2
A22: 0 | B22: 0 | C22: 0 | D22: 0 | E22: 0 | F22: تأهيل المؤسسات التعليمية | G22: 1032 | H22: 2020 | I22: 20 | J22: 4 | K22: 2
A23: 0 | B23: 700000 | C23: 0 | D23: 0 | E23: 700000 | F23: الملاعب و المركبات الرياضية | G23: 3110 | H23: 4040 | I23: 20 | J23: 4 | K23: 2
A24: 0 | B24: 1142318.5 | C24: 0 | D24: 0 | E24: 1142318.5 | F24: دراسات عامة | G24: 1110 | H24: 1010 | I24: 30 | J24: 4 | K24: 2
A25: 0 | B25: 873291.47 | C25: 70548 | D25: 415027.37 | E25: 943839.47 | F25: الدراسات العامة | G25: 1210 | H25: 1010 | I25: 30 | J25: 4 | K25: 2
A26: 0 | B26: 1646698.6 | C26: 0 | D26: 0 | E26: 1646698.6 | F26: المسالك والممرات الجماعية | G26: 1310 | H26: 2020 | I26: 30 | J26: 4 | K26: 2
A27: 0 | B27: 287706.14 | C27: 0 | D27: 180210.98 | E27: 287706.14 | F27: الجسور | G27: 2110 | H27: 2020 | I27: 30 | J27: 4 | K27: 2
A28: 0 | B28: 2026734.5 | C28: 1245865.2 | D28: 1653732.8 | E28: 3272599.6 | F28: جلب الماء الصالح للشرب | G28: 1120 | H28: 2020 | I28: 30 | J28: 4 | K28: 2
A29: 0 | B29: 246300 | C29: 53700 | D29: 53700 | E29: 300000 | F29: محطات الرفع والضخ | G29: 1420 | H29: 2020 | I29: 30 | J29: 4 | K29: 2
A30: 0 | B30: 175675.19 | C30: 0 | D30: 0 | E30: 175675.19 | F30: حفر الابار | G30: 1520 | H30: 2020 | I30: 30 | J30: 4 | K30: 2
A31: 0 | B31: 101827.26 | C31: 0 | D31: 0 | E31: 101827.26 | F31: نقط الماء العمومي | G31: 3120 | H31: 2020 | I31: 30 | J31: 4 | K31: 2
A32: 0 | B32: 391640.53 | C32: 0 | D32: 6742.53 | E32: 391640.53 | F32: وضع الاعمدة والاسلاك | G32: 2130 | H32: 2020 | I32: 30 | J32: 4 | K32: 2
A33: 0 | B33: 200000 | C33: 0 | D33: 0 | E33: 200000 | F33: الاعمدة والاسلاك | G33: 1130 | H33: 2020 | I33: 30 | J33: 4 | K33: 2
A34: 0 | B34: 220000 | C34: 282600 | D34: 32620 | E34: 502600 | F34: الدراسات والمساعدات التقنية | G34: 1021 | H34: 1010 | I34: 40 | J34: 4 | K34: 2
A35: 0 | B35: 0 | C35: 0 | D35: 0 | E35: 0 | F35: الحقوق والرسوم المرتبطة بالشراءات | G35: 1310 | H35: 3030 | I35: 40 | J35: 4 | K35: 2
... A42: 0 | B42: 0 | C42: 0 | D42: 0 | E42: 0 | F42: تغطية الاعتمادات المرحلة من نفقات التسيير | G42: 1210 | H42: 1010 | I42: 60 | J42: 4 | K42: 2
A43: 0 | B43: 9980398.9 | C43: 2188683.8 | D43: 3006674.1 | E43: 12169083 | F43: المجموع
C45: حررببومالن دادس بتاريخ 2024/12/31 | J45: حرربسوق الخميس دادس بتاريخ 2024/12/31 | M45: =#REF! -> 0
C46: تأشيرة المحاسب المختص لميزانية جماعة سوق الخميس دادس | J46: رئيس جماعة سوق الخميس دادس | M46: =#REF! -> 0
M47: =#REF! -> 0
M48: =#REF! -> 0
M49: 11399125
...
